2022-04-06 16:06:14,025 - web - ERROR - Traceback (most recent call last):
  File "/home/tpljqj/testDaemon/daemon/ConnectMQ.py", line 44, in push_path_to_MQ
    sender.send(path)
  File "/home/tpljqj/testDaemon/MQ/mq.py", line 23, in send
    #print(10/0)
ZeroDivisionError: division by zero

During handling of the above exception, another exception occurred:

Traceback (most recent call last):
  File "/home/tpljqj/testDaemon/daemon/ConnectWeb.py", line 69, in do_POST
    push_path_to_MQ(new_path) #放入消息队列
  File "/home/tpljqj/testDaemon/daemon/ConnectMQ.py", line 61, in push_path_to_MQ
    raise Exception
Exception

