2022-04-06 16:49:24,538 - web - ERROR - Traceback (most recent call last):
  File "/home/tpljqj/testDaemon/daemon/ConnectWeb.py", line 131, in Add_software
    #下载失败
  File "/home/tpljqj/.local/lib/python3.9/site-packages/git/repo/base.py", line 1148, in clone_from
    return cls._clone(git, url, to_path, GitCmdObjectDB, progress, multi_options, **kwargs)
  File "/home/tpljqj/.local/lib/python3.9/site-packages/git/repo/base.py", line 1086, in _clone
    finalize_process(proc, stderr=stderr)
  File "/home/tpljqj/.local/lib/python3.9/site-packages/git/util.py", line 386, in finalize_process
    proc.wait(**kwargs)
  File "/home/tpljqj/.local/lib/python3.9/site-packages/git/cmd.py", line 502, in wait
    raise GitCommandError(remove_password_if_present(self.args), status, errstr)
git.exc.GitCommandError: Cmd('git') failed due to: exit code(128)
  cmdline: git clone -v git@github.com:JustQJ/test.git /home/tpljqj/testDaemon/daemon/softwareHub/test
  stderr: 'fatal: destination path '/home/tpljqj/testDaemon/daemon/softwareHub/test' already exists and is not an empty directory.
'

During handling of the above exception, another exception occurred:

Traceback (most recent call last):
  File "/home/tpljqj/testDaemon/daemon/ConnectWeb.py", line 62, in do_POST
    new_path = self.Add_software(res['name'],res['address'])
  File "/home/tpljqj/testDaemon/daemon/ConnectWeb.py", line 133, in Add_software
    newrepo = git.Repo.clone_from(url=address,to_path=os.path.join(pkgs_path,name)) #下载
Exception

2022-04-06 16:49:24,538 - web - ERROR - Traceback (most recent call last):
  File "/home/tpljqj/testDaemon/daemon/ConnectWeb.py", line 77, in do_POST
    modifyDatabase(os.path.basename(new_path),state)
UnboundLocalError: local variable 'new_path' referenced before assignment

2022-04-06 16:49:39,809 - web - ERROR - Traceback (most recent call last):
  File "/home/tpljqj/testDaemon/daemon/ConnectWeb.py", line 131, in Add_software
    #下载失败
  File "/home/tpljqj/.local/lib/python3.9/site-packages/git/repo/base.py", line 1148, in clone_from
    return cls._clone(git, url, to_path, GitCmdObjectDB, progress, multi_options, **kwargs)
  File "/home/tpljqj/.local/lib/python3.9/site-packages/git/repo/base.py", line 1086, in _clone
    finalize_process(proc, stderr=stderr)
  File "/home/tpljqj/.local/lib/python3.9/site-packages/git/util.py", line 386, in finalize_process
    proc.wait(**kwargs)
  File "/home/tpljqj/.local/lib/python3.9/site-packages/git/cmd.py", line 502, in wait
    raise GitCommandError(remove_password_if_present(self.args), status, errstr)
git.exc.GitCommandError: Cmd('git') failed due to: exit code(128)
  cmdline: git clone -v git@ghub.com:JustQJ/test1.git /home/tpljqj/testDaemon/daemon/softwareHub/test1
  stderr: 'Cloning into '/home/tpljqj/testDaemon/daemon/softwareHub/test1'...
ssh: Could not resolve hostname ghub.com: No address associated with hostname
fatal: Could not read from remote repository.

Please make sure you have the correct access rights
and the repository exists.
'

During handling of the above exception, another exception occurred:

Traceback (most recent call last):
  File "/home/tpljqj/testDaemon/daemon/ConnectWeb.py", line 62, in do_POST
    new_path = self.Add_software(res['name'],res['address'])
  File "/home/tpljqj/testDaemon/daemon/ConnectWeb.py", line 133, in Add_software
    newrepo = git.Repo.clone_from(url=address,to_path=os.path.join(pkgs_path,name)) #下载
Exception

2022-04-06 16:49:39,809 - web - ERROR - Traceback (most recent call last):
  File "/home/tpljqj/testDaemon/daemon/ConnectWeb.py", line 77, in do_POST
    modifyDatabase(os.path.basename(new_path),state)
UnboundLocalError: local variable 'new_path' referenced before assignment

